<?xml version="1.0"?>
<robot xmlns:xacro="http://www.ros.org/wiki/xacro" name="tb3_burger">

<xacro:include filename="$(find ros2_urdf_project)/xacro/actuators.xacro" />
<xacro:include filename="$(find ros2_urdf_project)/xacro/chassis.xacro" />
<xacro:include filename="$(find ros2_urdf_project)/xacro/electronics.xacro" />
<xacro:include filename="$(find ros2_urdf_project)/xacro/model_plugins.xacro" />
<xacro:include filename="$(find ros2_urdf_project)/xacro/physical_properties.xacro" />
<xacro:include filename="$(find ros2_urdf_project)/xacro/rviz_materials.xacro" />
<xacro:include filename="$(find ros2_urdf_project)/xacro/sensor_plugins.xacro" />
<xacro:include filename="$(find ros2_urdf_project)/xacro/sensors.xacro" />
<xacro:include filename="$(find ros2_urdf_project)/xacro/tb3_burger.gazebo.xacro" />
<xacro:include filename="$(find ros2_urdf_project)/xacro/wheels.xacro" />

<xacro:chassis_plate chassis_plate_name="chassis_plate_1"/>
<xacro:chassis_plate chassis_plate_name="chassis_plate_2"/>
<xacro:chassis_plate chassis_plate_name="chassis_plate_3"/>
<xacro:chassis_plate chassis_plate_name="chassis_plate_4"/>

<xacro:spacer35 spacer35_name="spacer35_1"/>
<xacro:spacer35 spacer35_name="spacer35_2"/>
<xacro:spacer35 spacer35_name="spacer35_3"/>
<xacro:spacer35 spacer35_name="spacer35_4"/>

<xacro:spacer45 spacer45_name="spacer45_1"/>
<xacro:spacer45 spacer45_name="spacer45_2"/>
<xacro:spacer45 spacer45_name="spacer45_3"/>
<xacro:spacer45 spacer45_name="spacer45_4"/>
<xacro:spacer45 spacer45_name="spacer45_5"/>
<xacro:spacer45 spacer45_name="spacer45_6"/>
<xacro:spacer45 spacer45_name="spacer45_7"/>
<xacro:spacer45 spacer45_name="spacer45_8"/>
<xacro:spacer45 spacer45_name="spacer45_9"/>
<xacro:spacer45 spacer45_name="spacer45_10"/>

<xacro:drive_motor drive_motor_name="drive_motor_1"/>
<xacro:drive_motor drive_motor_name="drive_motor_2"/>

<xacro:battery/>

<xacro:control_board/>
<xacro:raspi_board/>

<xacro:state_publisher/>
<xacro:differential_drive/>
<xacro:ros2_control/>

<xacro:rviz_materials/>

<xacro:lidar_plugin/>
<xacro:camera_plugin/>
<xacro:imu_plugin/>

<xacro:imu_chip/>
<xacro:camera/>
<xacro:lidar/>

<xacro:gazebo_elements/>

<xacro:wheel wheel_name="left_wheel"/>
<xacro:wheel wheel_name="right_wheel"/>

<xacro:caster_wheel/>

  <!-- Base link-->
  <link name="base_link"/>
  
  <!-- Chassis plate 1 joint-->
  <joint name="chassis_plate_1_joint" type="fixed">
    <origin rpy="0 0 0" xyz="0 0 0.010"/>
    <parent link="base_link"/>
    <child link="chassis_plate_1_link"/>
  </joint>

  <joint name="spacer45_1_joint" type="fixed">
    <origin rpy="0 0 0" xyz="-0.06375 -0.025 0.018"/>
    <parent link="chassis_plate_1_link"/>
    <child link="spacer45_1_link"/>
  </joint>

  <joint name="spacer45_2_joint" type="fixed">
    <origin rpy="0 0 0" xyz="-0.06375 0.025 0.018"/>
    <parent link="chassis_plate_1_link"/>
    <child link="spacer45_2_link"/>
  </joint>

  <joint name="spacer45_3_joint" type="fixed">
    <origin rpy="0 0 0" xyz="0.06375 -0.025 0.018"/>
    <parent link="chassis_plate_1_link"/>
    <child link="spacer45_3_link"/>
  </joint>

  <joint name="spacer45_4_joint" type="fixed">
    <origin rpy="0 0 0" xyz="0.06375 0.025 0.018"/>
    <parent link="chassis_plate_1_link"/>
    <child link="spacer45_4_link"/>
  </joint>

  <!-- Drive motors joints-->
  <joint name="drive_motor_1_joint" type="fixed">
    <origin rpy="0 0 0" xyz="0.0255 0.05175 0.01875"/>
    <parent link="chassis_plate_1_link"/>
    <child link="drive_motor_1_link"/>
  </joint>

  <joint name="drive_motor_2_joint" type="fixed">
    <origin rpy="0 0 0" xyz="0.0255 -0.05175 0.01875"/>
    <parent link="chassis_plate_1_link"/>
    <child link="drive_motor_2_link"/>
  </joint>

  <!-- Wheel joint -->
  <joint name="left_wheel_joint" type="continuous">
    <origin rpy="0 1.571 1.571" xyz="0.012 0.0259 0"/>
    <parent link="drive_motor_1_link"/>
    <child link="left_wheel_link"/>
    <axis rpy="0 0 0" xyz="0 0 1"/>
    <limit effort="10000" velocity="1000"/>
    <joint_properties damping="1.0" friction="1.0"/>
  </joint>
  
  <joint name="right_wheel_joint" type="continuous">
    <origin rpy="0 1.571 1.571" xyz="0.012 -0.0259 0"/>
    <parent link="drive_motor_2_link"/>
    <child link="right_wheel_link"/>
    <axis rpy="0 0 0" xyz="0 0 1"/>
    <limit effort="10000" velocity="1000"/>
    <joint_properties damping="1.0" friction="1.0"/>
  </joint>

  <!-- Caster wheel joint -->
  <joint name="caster_wheel_support_joint" type="fixed">
    <origin rpy="0 0 0" xyz="-0.04875 0 -0.0085"/>
    <parent link="chassis_plate_1_link"/>
    <child link="caster_wheel_support_link"/>
  </joint>

  <joint name="caster_wheel_yaw_joint" type="continuous">
    <origin rpy="0 0 0" xyz="0 0 -0.004"/>
    <parent link="caster_wheel_support_link"/>
    <child link="caster_wheel_yaw_link"/>
    <axis xyz="0 0 1"/>
    <limit effort="1000.0" velocity="100.0"/>
    <dynamics damping="0.0" friction="0.1"/>
  </joint>

  <joint name="caster_wheel_roll_joint" type="continuous">
    <origin rpy="0 0 0" xyz="0 0 0"/>
    <parent link="caster_wheel_yaw_link"/>
    <child link="caster_wheel_roll_link"/>
    <axis xyz="1 0 0"/>
    <limit effort="1000.0" velocity="100.0"/>
    <dynamics damping="0.0" friction="0.1"/>
  </joint>

  <joint name="caster_wheel_pitch_joint" type="continuous">
    <origin rpy="0 0 0" xyz="0 0 0"/>
    <parent link="caster_wheel_roll_link"/>
    <child link="caster_wheel_pitch_link"/>
    <axis xyz="0 1 0"/>
    <limit effort="1000.0" velocity="100.0"/>
    <dynamics damping="0.0" friction="0.1"/>
  </joint>

  <!-- Battery joint -->
  <joint name="battery_joint" type="fixed">
    <origin rpy="0 0 0" xyz="0.011625 0 0.01825"/>
    <parent link="chassis_plate_1_link"/>
    <child link="battery_link"/>
  </joint>

  <!-- Chassis plate 2 joint-->
  <joint name="chassis_plate_2_joint" type="fixed">
    <origin rpy="0 0 0" xyz="0 0 0.0375"/>
    <parent link="chassis_plate_1_link"/>
    <child link="chassis_plate_2_link"/>
  </joint>

  <joint name="spacer35_1_joint" type="fixed">
    <origin rpy="0 0 0" xyz="-0.024 -0.06375 0.018"/>
    <parent link="chassis_plate_2_link"/>
    <child link="spacer35_1_link"/>
  </joint>

  <joint name="spacer35_2_joint" type="fixed">
    <origin rpy="0 0 0" xyz="-0.024 0.06375 0.018"/>
    <parent link="chassis_plate_2_link"/>
    <child link="spacer35_2_link"/>
  </joint>

  <joint name="spacer35_3_joint" type="fixed">
    <origin rpy="0 0 0" xyz="0.06375 -0.0125 0.018"/>
    <parent link="chassis_plate_2_link"/>
    <child link="spacer35_3_link"/>
  </joint>

  <joint name="spacer35_4_joint" type="fixed">
    <origin rpy="0 0 0" xyz="0.06375 0.0125 0.018"/>
    <parent link="chassis_plate_2_link"/>
    <child link="spacer35_4_link"/>
  </joint>

  <joint name="control_board_joint" type="fixed">
    <origin rpy="0 0 0" xyz="0 0 0.0125"/>
    <parent link="chassis_plate_2_link"/>
    <child link="control_board_link"/>
  </joint>

  <!-- Chassis plate 3 joint-->
  <joint name="chassis_plate_3_joint" type="fixed">
    <origin rpy="0 0 0" xyz="0 0 0.0375"/>
    <parent link="chassis_plate_2_link"/>
    <child link="chassis_plate_3_link"/>
  </joint>

  <joint name="spacer45_5_joint" type="fixed">
    <origin rpy="0 0 0" xyz="0.06375 -0.025 0.018"/>
    <parent link="chassis_plate_3_link"/>
    <child link="spacer45_5_link"/>
  </joint>

  <joint name="spacer45_6_joint" type="fixed">
    <origin rpy="0 0 0" xyz="0.06375 0.025 0.018"/>
    <parent link="chassis_plate_3_link"/>
    <child link="spacer45_6_link"/>
  </joint>

  <joint name="spacer45_7_joint" type="fixed">
    <origin rpy="0 0 0" xyz="0.06375 -0.025 0.018"/>
    <parent link="chassis_plate_3_link"/>
    <child link="spacer45_7_link"/>
  </joint>

  <joint name="spacer45_8_joint" type="fixed">
    <origin rpy="0 0 0" xyz="0.06375 0.025 0.018"/>
    <parent link="chassis_plate_3_link"/>
    <child link="spacer45_8_link"/>
  </joint>

  <joint name="spacer45_9_joint" type="fixed">
    <origin rpy="0 0 0" xyz="0.024 -0.06375 0.018"/>
    <parent link="chassis_plate_3_link"/>
    <child link="spacer45_9_link"/>
  </joint>

  <joint name="spacer45_10_joint" type="fixed">
    <origin rpy="0 0 0" xyz="0.024 0.06375 0.018"/>
    <parent link="chassis_plate_3_link"/>
    <child link="spacer45_10_link"/>
  </joint>

  <!-- Raspberry Pi board joint -->
  <joint name="raspi_board_joint" type="fixed">
    <origin rpy="0 0 0" xyz="-0.030 0 0.01475"/>
    <parent link="chassis_plate_3_link"/>
    <child link="raspi_board_link"/>
  </joint>

  <!-- Lidar USB board joint -->
  <joint name="imu_chip_joint" type="fixed">
    <origin rpy="0 0 0" xyz="0.015 0 0.00675"/>
    <parent link="chassis_plate_3_link"/>
    <child link="imu_chip_link"/>
  </joint>

  <!-- Camera joint -->
  <joint name="camera_support_joint" type="fixed">
    <origin rpy="0 0 0" xyz="0.06625 0 0.01"/>
    <parent link="chassis_plate_3_link"/>
    <child link="camera_support_link"/>
  </joint>

  <joint name="camera_joint" type="fixed">
    <origin rpy="0 0 0" xyz="0.005 0 -0.0075"/>
    <parent link="camera_support_link"/>
    <child link="camera_link"/>
  </joint>

  <!-- Chassis plate 4 joint-->
  <joint name="chassis_plate_4_joint" type="fixed">
    <origin rpy="0 0 0" xyz="0 0 0.0375"/>
    <parent link="chassis_plate_3_link"/>
    <child link="chassis_plate_4_link"/>
  </joint>

  <!-- Lidar -->
  <joint name="lidar_support_joint" type="fixed">
    <origin rpy="0 0 3.142" xyz="0 0 0.01735"/>
    <parent link="chassis_plate_4_link"/>
    <child link="lidar_support_link"/>
  </joint>

  <joint name="lidar_spinner_joint" type="continuous">
    <origin rpy="0 0 0" xyz="0 0 0.02225"/>
    <parent link="lidar_support_link"/>
    <child link="lidar_spinner_link"/>
    <axis xyz="0 0 1"/>
    <limit effort="10.0" velocity="2.0"/>
    <dynamics friction="0.01"/>
  </joint>

</robot>