<?xml version="1.0"?>
<robot name="tb3_burger">

  <!-- Materials -->
  <material name="white">
      <color rgba="1.0 1.0 1.0 1"/>
  </material>
  
  <material name="black">
    <color rgba="0 0 0 1"/>
  </material>
  
  <material name="dark">
    <color rgba="0.3 0.3 0.3 1"/>
  </material>
  
  <material name="grey">
    <color rgba="0.5 0.5 0.5 1"/>
  </material>
  
  <material name="red">
    <color rgba="0.8 0.0 0.0 1"/>
  </material>
  
  <material name="blue">
    <color rgba="0.0 0.0 0.8 1"/>
  </material>
  
  <material name="green">
    <color rgba="0.0 0.8 0.0 1"/>
  </material>
  
  <material name="yellow">
    <color rgba="0.8 0.8 0.0 1"/>
  </material>

  <material name="magenta">
    <color rgba="0.8 0.0 0.8 1"/>
  </material>
  
  <material name="cyan">
    <color rgba="0.0 0.8 0.8 1"/>
  </material>

  <!-- Base link -->
  <link name="base_link"/>
  
  <!-- Chassis plates link -->
  <link name="chassis_plate_1_link">
    <visual>
      <geometry>
        <box size="0.1375 0.1375 0.009"/>
      </geometry>
      <material name="black"/>
    </visual>

    <collision>
      <geometry>
        <box size="0.1375 0.1375 0.009"/>
      </geometry>
    </collision>

    <inertial>
      <mass value="0.035"/>
      <inertia ixx="5.5e-05" ixy="0.0e+00" ixz="0.0e+00" iyy="5.5e-05" iyz="0.0e+00" izz="1.1e-04"/>
    </inertial>
  </link>

  <gazebo reference="chassis_plate_1_link">
    <material>Gazebo/Black</material>
  </gazebo>

  <link name="chassis_plate_2_link">
    <visual>
      <geometry>
        <box size="0.1375 0.1375 0.009"/>
      </geometry>
      <material name="black"/>
    </visual>

    <collision>
      <geometry>
        <box size="0.1375 0.1375 0.009"/>
      </geometry>
    </collision>

    <inertial>
      <mass value="0.035"/>
      <inertia ixx="5.5e-05" ixy="0.0e+00" ixz="0.0e+00" iyy="5.5e-05" iyz="0.0e+00" izz="1.1e-04"/>
    </inertial>
  </link>

  <gazebo reference="chassis_plate_2_link">
    <material>Gazebo/Black</material>
  </gazebo>

  <link name="chassis_plate_3_link">
    <visual>
      <geometry>
        <box size="0.1375 0.1375 0.009"/>
      </geometry>
      <material name="black"/>
    </visual>

    <collision>
      <geometry>
        <box size="0.1375 0.1375 0.009"/>
      </geometry>
    </collision>

    <inertial>
      <mass value="0.035"/>
      <inertia ixx="5.5e-05" ixy="0.0e+00" ixz="0.0e+00" iyy="5.5e-05" iyz="0.0e+00" izz="1.1e-04"/>
    </inertial>
  </link>

  <gazebo reference="chassis_plate_3_link">
    <material>Gazebo/Black</material>
  </gazebo>

  <link name="chassis_plate_4_link">
    <visual>
      <geometry>
        <box size="0.1375 0.1375 0.009"/>
      </geometry>
      <material name="black"/>
    </visual>

    <collision>
      <geometry>
        <box size="0.1375 0.1375 0.009"/>
      </geometry>
    </collision>

    <inertial>
      <mass value="0.035"/>
      <inertia ixx="5.5e-05" ixy="0.0e+00" ixz="0.0e+00" iyy="5.5e-05" iyz="0.0e+00" izz="1.1e-04"/>
    </inertial>
  </link>

  <gazebo reference="chassis_plate_4_link">
    <material>Gazebo/Black</material>
  </gazebo>

  <!-- PCB mounts links -->
  <!-- <link name="pcb_mount_1_link">
    <visual>
      <geometry>
        <box size="0.03782 0.010 0.010"/>
      </geometry>
      <material name="grey"/>
    </visual>

    <collision>
      <geometry>
        <box size="0.03782 0.010 0.010"/>
      </geometry>
    </collision>

    <inertial>
      <mass value="0.005"/>
      <inertia ixx="8.3e-08" ixy="0.0e+00" ixz="0.0e+00" iyy="6.4e-07" iyz="0.0e+00" izz="6.4e-07"/>
    </inertial>
  </link>

  <link name="pcb_mount_2_link">
    <visual>
      <geometry>
        <box size="0.03782 0.010 0.010"/>
      </geometry>
      <material name="grey"/>
    </visual>

    <collision>
      <geometry>
        <box size="0.03782 0.010 0.010"/>
      </geometry>
    </collision>

    <inertial>
      <mass value="0.005"/>
      <inertia ixx="8.3e-08" ixy="0.0e+00" ixz="0.0e+00" iyy="6.4e-07" iyz="0.0e+00" izz="6.4e-07"/>
    </inertial>
  </link>

  <link name="pcb_mount_3_link">
    <visual>
      <geometry>
        <box size="0.03782 0.010 0.010"/>
      </geometry>
      <material name="grey"/>
    </visual>

    <collision>
      <geometry>
        <box size="0.03782 0.010 0.010"/>
      </geometry>
    </collision>

    <inertial>
      <mass value="0.005"/>
      <inertia ixx="8.3e-08" ixy="0.0e+00" ixz="0.0e+00" iyy="6.4e-07" iyz="0.0e+00" izz="6.4e-07"/>
    </inertial>
  </link>

  <link name="pcb_mount_4_link">
    <visual>
      <geometry>
        <box size="0.03782 0.010 0.010"/>
      </geometry>
      <material name="grey"/>
    </visual>

    <collision>
      <geometry>
        <box size="0.03782 0.010 0.010"/>
      </geometry>
    </collision>

    <inertial>
      <mass value="0.005"/>
      <inertia ixx="8.3e-08" ixy="0.0e+00" ixz="0.0e+00" iyy="6.4e-07" iyz="0.0e+00" izz="6.4e-07"/>
    </inertial>
  </link>

  <link name="pcb_mount_5_link">
    <visual>
      <geometry>
        <box size="0.03782 0.010 0.010"/>
      </geometry>
      <material name="grey"/>
    </visual>

    <collision>
      <geometry>
        <box size="0.03782 0.010 0.010"/>
      </geometry>
    </collision>

    <inertial>
      <mass value="0.005"/>
      <inertia ixx="8.3e-08" ixy="0.0e+00" ixz="0.0e+00" iyy="6.4e-07" iyz="0.0e+00" izz="6.4e-07"/>
    </inertial>
  </link>

  <link name="pcb_mount_6_link">
    <visual>
      <geometry>
        <box size="0.03782 0.010 0.010"/>
      </geometry>
      <material name="grey"/>
    </visual>

    <collision>
      <geometry>
        <box size="0.03782 0.010 0.010"/>
      </geometry>
    </collision>

    <inertial>
      <mass value="0.005"/>
      <inertia ixx="8.3e-08" ixy="0.0e+00" ixz="0.0e+00" iyy="6.4e-07" iyz="0.0e+00" izz="6.4e-07"/>
    </inertial>
  </link>

  <link name="pcb_mount_7_link">
    <visual>
      <geometry>
        <box size="0.03782 0.010 0.010"/>
      </geometry>
      <material name="grey"/>
    </visual>

    <collision>
      <geometry>
        <box size="0.03782 0.010 0.010"/>
      </geometry>
    </collision>

    <inertial>
      <mass value="0.005"/>
      <inertia ixx="8.3e-08" ixy="0.0e+00" ixz="0.0e+00" iyy="6.4e-07" iyz="0.0e+00" izz="6.4e-07"/>
    </inertial>
  </link>

  <link name="pcb_mount_8_link">
    <visual>
      <geometry>
        <box size="0.03782 0.010 0.010"/>
      </geometry>
      <material name="grey"/>
    </visual>

    <collision>
      <geometry>
        <box size="0.03782 0.010 0.010"/>
      </geometry>
    </collision>

    <inertial>
      <mass value="0.005"/>
      <inertia ixx="8.3e-08" ixy="0.0e+00" ixz="0.0e+00" iyy="6.4e-07" iyz="0.0e+00" izz="6.4e-07"/>
    </inertial>
  </link>

  <link name="pcb_mount_9_link">
    <visual>
      <geometry>
        <box size="0.03782 0.010 0.010"/>
      </geometry>
      <material name="grey"/>
    </visual>

    <collision>
      <geometry>
        <box size="0.03782 0.010 0.010"/>
      </geometry>
    </collision>

    <inertial>
      <mass value="0.005"/>
      <inertia ixx="8.3e-08" ixy="0.0e+00" ixz="0.0e+00" iyy="6.4e-07" iyz="0.0e+00" izz="6.4e-07"/>
    </inertial>
  </link>

  <link name="pcb_mount_10_link">
    <visual>
      <geometry>
        <box size="0.03782 0.010 0.010"/>
      </geometry>
      <material name="grey"/>
    </visual>

    <collision>
      <geometry>
        <box size="0.03782 0.010 0.010"/>
      </geometry>
    </collision>

    <inertial>
      <mass value="0.005"/>
      <inertia ixx="8.3e-08" ixy="0.0e+00" ixz="0.0e+00" iyy="6.4e-07" iyz="0.0e+00" izz="6.4e-07"/>
    </inertial>
  </link>

  <link name="pcb_mount_11_link">
    <visual>
      <geometry>
        <box size="0.03782 0.010 0.010"/>
      </geometry>
      <material name="grey"/>
    </visual>

    <collision>
      <geometry>
        <box size="0.03782 0.010 0.010"/>
      </geometry>
    </collision>

    <inertial>
      <mass value="0.005"/>
      <inertia ixx="8.3e-08" ixy="0.0e+00" ixz="0.0e+00" iyy="6.4e-07" iyz="0.0e+00" izz="6.4e-07"/>
    </inertial>
  </link>

  <link name="pcb_mount_12_link">
    <visual>
      <geometry>
        <box size="0.03782 0.010 0.010"/>
      </geometry>
      <material name="grey"/>
    </visual>

    <collision>
      <geometry>
        <box size="0.03782 0.010 0.010"/>
      </geometry>
    </collision>

    <inertial>
      <mass value="0.005"/>
      <inertia ixx="8.3e-08" ixy="0.0e+00" ixz="0.0e+00" iyy="6.4e-07" iyz="0.0e+00" izz="6.4e-07"/>
    </inertial>
  </link> -->
  
  <!-- Spacers (35mm) link -->
  <link name="spacer35_1_link">
    <visual>
      <geometry>
        <cylinder radius="0.0025" length="0.035"/>
      </geometry>
      <material name="grey"/>
    </visual>

    <collision>
      <geometry>
        <cylinder radius="0.0025" length="0.035"/>
      </geometry>
    </collision>

    <inertial>
      <mass value="0.007"/>
      <inertia ixx="7.3e-07" ixy="0.0e+00" ixz="0.0e+00" iyy="7.3e-07" iyz="0.0e+00" izz="2.2e-08"/>
    </inertial>
  </link>

  <gazebo reference="spacer35_1_link">
    <material>Gazebo/Grey</material>
  </gazebo>
  
  <link name="spacer35_2_link">
    <visual>
      <geometry>
        <cylinder radius="0.0025" length="0.035"/>
      </geometry>
      <material name="grey"/>
    </visual>

    <collision>
      <geometry>
        <cylinder radius="0.0025" length="0.035"/>
      </geometry>
    </collision>

    <inertial>
      <mass value="0.007"/>
      <inertia ixx="7.3e-07" ixy="0.0e+00" ixz="0.0e+00" iyy="7.3e-07" iyz="0.0e+00" izz="2.2e-08"/>
    </inertial>
  </link>

  <gazebo reference="spacer35_2_link">
    <material>Gazebo/Grey</material>
  </gazebo>
  
  <link name="spacer35_3_link">
    <visual>
      <geometry>
        <cylinder radius="0.0025" length="0.035"/>
      </geometry>
      <material name="grey"/>
    </visual>

    <collision>
      <geometry>
        <cylinder radius="0.0025" length="0.035"/>
      </geometry>
    </collision>

    <inertial>
      <mass value="0.007"/>
      <inertia ixx="7.3e-07" ixy="0.0e+00" ixz="0.0e+00" iyy="7.3e-07" iyz="0.0e+00" izz="2.2e-08"/>
    </inertial>
  </link>

  <gazebo reference="spacer35_3_link">
    <material>Gazebo/Grey</material>
  </gazebo>
  
  <link name="spacer35_4_link">
    <visual>
      <geometry>
        <cylinder radius="0.0025" length="0.035"/>
      </geometry>
      <material name="grey"/>
    </visual>

    <collision>
      <geometry>
        <cylinder radius="0.0025" length="0.035"/>
      </geometry>
    </collision>

    <inertial>
      <mass value="0.007"/>
      <inertia ixx="7.3e-07" ixy="0.0e+00" ixz="0.0e+00" iyy="7.3e-07" iyz="0.0e+00" izz="2.2e-08"/>
    </inertial>
  </link>

  <gazebo reference="spacer35_4_link">
    <material>Gazebo/Grey</material>
  </gazebo>
  
  <!-- Spacers (45mm) link -->
  <link name="spacer45_1_link">
    <visual>
      <geometry>
        <cylinder radius="0.0025" length="0.045"/>
      </geometry>
      <material name="grey"/>
    </visual>

    <collision>
      <geometry>
        <cylinder radius="0.0025" length="0.045"/>
      </geometry>
    </collision>

    <inertial>
      <mass value="0.009"/>
      <inertia ixx="1.5e-06" ixy="0.0e+00" ixz="0.0e+00" iyy="1.5e-06" iyz="0.0e+00" izz="2.8e-08"/>
    </inertial>
  </link>

  <gazebo reference="spacer45_1_link">
    <material>Gazebo/Grey</material>
  </gazebo>
  
  <link name="spacer45_2_link">
    <visual>
      <geometry>
        <cylinder radius="0.0025" length="0.045"/>
      </geometry>
      <material name="grey"/>
    </visual>

    <collision>
      <geometry>
        <cylinder radius="0.0025" length="0.045"/>
      </geometry>
    </collision>

    <inertial>
      <mass value="0.009"/>
      <inertia ixx="1.5e-06" ixy="0.0e+00" ixz="0.0e+00" iyy="1.5e-06" iyz="0.0e+00" izz="2.8e-08"/>
    </inertial>
  </link>

  <gazebo reference="spacer45_2_link">
    <material>Gazebo/Grey</material>
  </gazebo>
  
  <link name="spacer45_3_link">
    <visual>
      <geometry>
        <cylinder radius="0.0025" length="0.045"/>
      </geometry>
      <material name="grey"/>
    </visual>

    <collision>
      <geometry>
        <cylinder radius="0.0025" length="0.045"/>
      </geometry>
    </collision>

    <inertial>
      <mass value="0.009"/>
      <inertia ixx="1.5e-06" ixy="0.0e+00" ixz="0.0e+00" iyy="1.5e-06" iyz="0.0e+00" izz="2.8e-08"/>
    </inertial>
  </link>

  <gazebo reference="spacer45_3_link">
    <material>Gazebo/Grey</material>
  </gazebo>
  
  <link name="spacer45_4_link">
    <visual>
      <geometry>
        <cylinder radius="0.0025" length="0.045"/>
      </geometry>
      <material name="grey"/>
    </visual>

    <collision>
      <geometry>
        <cylinder radius="0.0025" length="0.045"/>
      </geometry>
    </collision>

    <inertial>
      <mass value="0.009"/>
      <inertia ixx="1.5e-06" ixy="0.0e+00" ixz="0.0e+00" iyy="1.5e-06" iyz="0.0e+00" izz="2.8e-08"/>
    </inertial>
  </link>

  <gazebo reference="spacer45_4_link">
    <material>Gazebo/Grey</material>
  </gazebo>
  
  <link name="spacer45_5_link">
    <visual>
      <geometry>
        <cylinder radius="0.0025" length="0.045"/>
      </geometry>
      <material name="grey"/>
    </visual>

    <collision>
      <geometry>
        <cylinder radius="0.0025" length="0.045"/>
      </geometry>
    </collision>

    <inertial>
      <mass value="0.009"/>
      <inertia ixx="1.5e-06" ixy="0.0e+00" ixz="0.0e+00" iyy="1.5e-06" iyz="0.0e+00" izz="2.8e-08"/>
    </inertial>
  </link>

  <gazebo reference="spacer45_5_link">
    <material>Gazebo/Grey</material>
  </gazebo>
  
  <link name="spacer45_6_link">
    <visual>
      <geometry>
        <cylinder radius="0.0025" length="0.045"/>
      </geometry>
      <material name="grey"/>
    </visual>

    <collision>
      <geometry>
        <cylinder radius="0.0025" length="0.045"/>
      </geometry>
    </collision>

    <inertial>
      <mass value="0.009"/>
      <inertia ixx="1.5e-06" ixy="0.0e+00" ixz="0.0e+00" iyy="1.5e-06" iyz="0.0e+00" izz="2.8e-08"/>
    </inertial>
  </link>

  <gazebo reference="spacer45_6_link">
    <material>Gazebo/Grey</material>
  </gazebo>
  
  <link name="spacer45_7_link">
    <visual>
      <geometry>
        <cylinder radius="0.0025" length="0.045"/>
      </geometry>
      <material name="grey"/>
    </visual>

    <collision>
      <geometry>
        <cylinder radius="0.0025" length="0.045"/>
      </geometry>
    </collision>

    <inertial>
      <mass value="0.009"/>
      <inertia ixx="1.5e-06" ixy="0.0e+00" ixz="0.0e+00" iyy="1.5e-06" iyz="0.0e+00" izz="2.8e-08"/>
    </inertial>
  </link>

  <gazebo reference="spacer45_7_link">
    <material>Gazebo/Grey</material>
  </gazebo>
  
  <link name="spacer45_8_link">
    <visual>
      <geometry>
        <cylinder radius="0.0025" length="0.045"/>
      </geometry>
      <material name="grey"/>
    </visual>

    <collision>
      <geometry>
        <cylinder radius="0.0025" length="0.045"/>
      </geometry>
    </collision>

    <inertial>
      <mass value="0.009"/>
      <inertia ixx="1.5e-06" ixy="0.0e+00" ixz="0.0e+00" iyy="1.5e-06" iyz="0.0e+00" izz="2.8e-08"/>
    </inertial>
  </link>

  <gazebo reference="spacer45_8_link">
    <material>Gazebo/Grey</material>
  </gazebo>
  
  <link name="spacer45_9_link">
    <visual>
      <geometry>
        <cylinder radius="0.0025" length="0.045"/>
      </geometry>
      <material name="grey"/>
    </visual>

    <collision>
      <geometry>
        <cylinder radius="0.0025" length="0.045"/>
      </geometry>
    </collision>

    <inertial>
      <mass value="0.009"/>
      <inertia ixx="1.5e-06" ixy="0.0e+00" ixz="0.0e+00" iyy="1.5e-06" iyz="0.0e+00" izz="2.8e-08"/>
    </inertial>
  </link>

  <gazebo reference="spacer45_9_link">
    <material>Gazebo/Grey</material>
  </gazebo>
  
  <link name="spacer45_10_link">
    <visual>
      <geometry>
        <cylinder radius="0.0025" length="0.045"/>
      </geometry>
      <material name="grey"/>
    </visual>

    <collision>
      <geometry>
        <cylinder radius="0.0025" length="0.045"/>
      </geometry>
    </collision>

    <inertial>
      <mass value="0.009"/>
      <inertia ixx="1.5e-06" ixy="0.0e+00" ixz="0.0e+00" iyy="1.5e-06" iyz="0.0e+00" izz="2.8e-08"/>
    </inertial>
  </link>

  <gazebo reference="spacer45_10_link">
    <material>Gazebo/Grey</material>
  </gazebo>

  <!-- Drive motors link -->
  <link name="drive_motor_1_link">
    <visual>
      <geometry>
        <box size="0.0465 0.034 0.0285"/>
      </geometry>
      <material name="grey"/>
    </visual>

    <collision>
      <geometry>
        <box size="0.0465 0.034 0.0285"/>
      </geometry>
    </collision>

    <inertial>
      <mass value="0.050"/>
      <inertia ixx="8.2e-06" ixy="0.0e+00" ixz="0.0e+00" iyy="1.2e-05" iyz="0.0e+00" izz="1.4e-05"/>
    </inertial>
  </link>

  <gazebo reference="drive_motor_1_link">
    <material>Gazebo/Grey</material>
  </gazebo>

  <link name="drive_motor_2_link">
    <visual>
      <geometry>
        <box size="0.0465 0.034 0.0285"/>
      </geometry>
      <material name="grey"/>
    </visual>

    <collision>
      <geometry>
        <box size="0.0465 0.034 0.0285"/>
      </geometry>
    </collision>

    <inertial>
      <mass value="0.050"/>
      <inertia ixx="8.2e-06" ixy="0.0e+00" ixz="0.0e+00" iyy="1.2e-05" iyz="0.0e+00" izz="1.4e-05"/>
    </inertial>
  </link>

  <gazebo reference="drive_motor_2_link">
    <material>Gazebo/Grey</material>
  </gazebo>

  <!-- Drive wheel axle -->
  <!-- <link name="drive_wheel_axle_1_link">
    <visual>
      <geometry>
        <cylinder radius="0.01025" length="0.00935"/>
      </geometry>
      <material name="black"/>
    </visual>

    <collision>
      <geometry>
        <cylinder radius="0.01025" length="0.00935"/>
      </geometry>
    </collision>

    <inertial>
      <mass value="0.010"/>
      <inertia ixx="3.4e-07" ixy="0.0e+00" ixz="0.0e+00" iyy="3.4e-07" iyz="0.0e+00" izz="5.3e-07"/>
    </inertial>
  </link> -->

  <!-- <link name="drive_wheel_axle_2_link">
    <visual>
      <geometry>
        <cylinder radius="0.01025" length="0.00935"/>
      </geometry>
      <material name="black"/>
    </visual>

    <collision>
      <geometry>
        <cylinder radius="0.01025" length="0.00935"/>
      </geometry>
    </collision>

    <inertial>
      <mass value="0.010"/>
      <inertia ixx="3.4e-07" ixy="0.0e+00" ixz="0.0e+00" iyy="3.4e-07" iyz="0.0e+00" izz="5.3e-07"/>
    </inertial>
  </link> -->
  
  <!-- Drive wheels link -->
  <link name="right_wheel_link">
    <visual>
      <geometry>
        <cylinder radius="0.033" length="0.0178"/>
      </geometry>
      <material name="dark"/>
    </visual>

    <collision>
      <geometry>
        <cylinder radius="0.033" length="0.0178"/>
      </geometry>
    </collision>

    <inertial>
      <mass value="0.025"/>
      <inertia ixx="7.5e-06" ixy="0.0e+00" ixz="0.0e+00" iyy="7.5e-06" iyz="0.0e+00" izz="1.4e-05"/>
    </inertial>
  </link>

  <gazebo reference="right_wheel_link">
    <kp>1000000000000000000000000000.0</kp>
    <kd>1000000000000000000000000000.0</kd>
    <mu1>10.0</mu1>
    <mu2>10.0</mu2>
    <material>Gazebo/DarkGrey</material>
  </gazebo>

  <link name="left_wheel_link">
    <visual>
      <geometry>
        <cylinder radius="0.033" length="0.0178"/>
      </geometry>
      <material name="dark"/>
    </visual>

    <collision>
      <geometry>
        <cylinder radius="0.033" length="0.0178"/>
      </geometry>
    </collision>

    <inertial>
      <mass value="0.025"/>
      <inertia ixx="7.5e-06" ixy="0.0e+00" ixz="0.0e+00" iyy="7.5e-06" iyz="0.0e+00" izz="1.4e-05"/>
    </inertial>
  </link>

  <gazebo reference="left_wheel_link">
    <kp>1000000000000000000000000000.0</kp>
    <kd>1000000000000000000000000000.0</kd>
    <mu1>10.0</mu1>
    <mu2>10.0</mu2>
    <material>Gazebo/DarkGrey</material>
  </gazebo>

  <!-- Caster wheel support link -->
  <link name="caster_wheel_support_link">
    <visual>
      <geometry>
        <box size="0.030 0.018 0.008"/>
      </geometry>
      <material name="dark"/>
    </visual>

    <collision>
      <geometry>
        <box size="0.030 0.018 0.008"/>
      </geometry>
    </collision>

    <inertial>
      <mass value="0.010"/>
      <inertia ixx="3.2e-07" ixy="0.0e+00" ixz="0.0e+00" iyy="8.0e-07" iyz="0.0e+00" izz="1.0e-06"/>
    </inertial>
  </link>

  <gazebo reference="caster_wheel_support_link">
    <material>Gazebo/DarkGrey</material>
  </gazebo>

  <!-- Caster wheel link -->
  <link name="caster_wheel_yaw_link">
      <visual>
        <origin rpy="0 1.5707 1.5707" xyz="0 0 0"/>
        <geometry>          
          <cylinder length="0.001" radius="0.0045000000000000005"/>
        </geometry>
        <material name="blue"/>
      </visual>

      <collision>
        <origin rpy="0 1.5707 1.5707" xyz="0 0 0"/>
        <geometry>
          <cylinder length="0.001" radius="0.0045000000000000005"/>
        </geometry>
      </collision>

      <inertial>
          <origin rpy="0 1.5707 1.5707" xyz="0 0 0"/>
          <mass value="0.001"/>
          <inertia ixx="5.145833333333334e-09" ixy="0" ixz="0" iyy="5.145833333333334e-09" iyz="0" izz="1.0125000000000003e-08"/>
      </inertial>
  </link>

  <gazebo reference="caster_wheel_yaw_link">
    <material>Gazebo/Blue</material>
  </gazebo>

  <link name="caster_wheel_roll_link">
      <visual>
        <origin rpy="0 1.5707 1.5707" xyz="0 0 0"/>
        <geometry>
          <cylinder length="0.001" radius="0.0045000000000000005"/>
        </geometry>
        <material name="red"/>
      </visual>

      <collision>
        <origin rpy="0 1.5707 1.5707" xyz="0 0 0"/>
        <geometry>
          <cylinder length="0.001" radius="0.0045000000000000005"/>
        </geometry>
      </collision>

      <inertial>
          <origin rpy="0 1.5707 1.5707" xyz="0 0 0"/>
          <mass value="0.001"/>
          <inertia ixx="5.145833333333334e-09" ixy="0" ixz="0" iyy="5.145833333333334e-09" iyz="0" izz="1.0125000000000003e-08"/>
      </inertial>
  </link>

  <gazebo reference="caster_wheel_roll_link">
    <material>Gazebo/Red</material>
  </gazebo>

  <link name="caster_wheel_pitch_link">
    <visual>
      <origin rpy="0 1.5707 1.5707" xyz="0 0 0"/>
      <geometry>
        <sphere radius="0.005"/>
      </geometry>
      <material name="grey"/>
    </visual>

    <collision>
      <origin rpy="0 1.5707 1.5707" xyz="0 0 0"/>
      <geometry>
        <sphere radius="0.005"/>
      </geometry>
    </collision>

    <inertial>
        <origin rpy="0 1.5707 1.5707" xyz="0 0 0"/>
        <mass value="0.010"/>
      <inertia ixx="1.0e-07" ixy="0.0e+00" ixz="0.0e+00" iyy="1.0e-07" iyz="0.0e+00" izz="1.0e-07" />
    </inertial>
  </link>

  <gazebo reference="caster_wheel_pitch_link">
    <kp>1e+27</kp>
    <kd>1e+27</kd>
    <mu1>0.5</mu1>
    <mu2>0.5</mu2>
    <material>Gazebo/Yellow</material>
  </gazebo>

  <!-- Control board link -->
  <link name="control_board_link">
    <visual>
      <geometry>
        <box size="0.105 0.075 0.016"/>
      </geometry>
      <material name="blue"/>
    </visual>

    <collision>
      <geometry>
        <box size="0.105 0.075 0.016"/>
      </geometry>
    </collision>

    <inertial>
      <mass value="0.060"/>
      <inertia ixx="2.9e-05" ixy="0.0e+00" ixz="0.0e+00" iyy="5.6e-05" iyz="0.0e+00" izz="8.3e-05"/>
    </inertial>
  </link>

  <gazebo reference="control_board_link">
    <material>Gazebo/Blue</material>
  </gazebo>

  <!-- IMU chip link -->
  <link name="imu_chip_link">
    <visual>
      <geometry>
        <box size="0.005 0.005 0.0025"/>
      </geometry>
      <material name="blue"/>
    </visual>

    <collision>
      <geometry>
        <box size="0.005 0.005 0.0025"/>
      </geometry>
    </collision>

    <inertial>
      <mass value="0.002"/>
      <inertia ixx="5.2e-09" ixy="0.0e+00" ixz="0.0e+00" iyy="5.2e-09" iyz="0.0e+00" izz="8.3e-09"/>
    </inertial>
  </link>

  <gazebo reference="imu_chip_link">
    <material>Gazebo/Blue</material>
  </gazebo>

  <!-- Raspberry Pi board link -->
  <link name="raspi_board_link">
    <visual>
      <geometry>
        <box size="0.058 0.090 0.01935"/>
      </geometry>
      <material name="red"/>
    </visual>

    <collision>
      <geometry>
        <box size="0.058 0.090 0.01935"/>
      </geometry>
    </collision>

    <inertial>
      <mass value="0.050"/>
      <inertia ixx="3.5e-05" ixy="0.0e+00" ixz="0.0e+00" iyy="1.6e-05" iyz="0.0e+00" izz="4.8e-05"/>
    </inertial>
  </link>

  <gazebo reference="raspi_board_link">
    <material>Gazebo/Red</material>
  </gazebo>

  <!-- Lidar USB board link -->
  <!-- <link name="lidar_usb_board_link">
    <visual>
      <geometry>
        <box size="0.018 0.030 0.0045"/>
      </geometry>
      <material name="blue"/>
    </visual>

    <collision>
      <geometry>
        <box size="0.018 0.030 0.0045"/>
      </geometry>
    </collision>

    <inertial>
      <mass value="0.010"/>
      <inertia ixx="7.7e-07" ixy="0.0e+00" ixz="0.0e+00" iyy="2.9e-07" iyz="0.0e+00" izz="1.0e-06"/>
    </inertial>
  </link>

  <gazebo reference="lidar_usb_board_link">
    <material>Gazebo/Blue</material>
  </gazebo> -->

  <!-- Camera support link -->
  <link name="camera_support_link">
    <visual>
      <geometry>
        <box size="0.005 0.030 0.015"/>
      </geometry>
      <material name="dark"/>
    </visual>

    <collision>
      <geometry>
        <box size="0.005 0.030 0.015"/>
      </geometry>
    </collision>

    <inertial>
      <mass value="0.010"/>
      <inertia ixx="9.4e-07" ixy="0.0e+00" ixz="0.0e+00" iyy="2.1e-07" iyz="0.0e+00" izz="7.7e-07"/>
    </inertial>
  </link>

  <gazebo reference="camera_support_link">
    <material>Gazebo/DarkGrey</material>
  </gazebo>

  <!-- Camera link -->
  <link name="camera_link">
    <visual>
      <geometry>
        <box size="0.005 0.030 0.030"/>
      </geometry>
      <material name="black"/>
    </visual>

    <collision>
      <geometry>
        <box size="0.005 0.030 0.030"/>
      </geometry>
    </collision>

    <inertial>
      <mass value="0.010"/>
      <inertia ixx="9.4e-07" ixy="0.0e+00" ixz="0.0e+00" iyy="2.1e-07" iyz="0.0e+00" izz="7.7e-07"/>
    </inertial>
  </link>

  <gazebo reference="camera_link">
    <material>Gazebo/Black</material>
  </gazebo>

  <!-- Lidar support link -->
  <link name="lidar_support_link">
    <visual>
      <geometry>
        <!-- <mesh filename="package://ros2_urdf_project/meshes/lds_base.dae" scale="0.001 0.001 0.001"/> -->
        <box size="0.0947 0.0727 0.0257"/>
      </geometry>
      <material name="dark"/>
    </visual>

    <collision>
      <geometry>
        <!-- <mesh filename="package://ros2_urdf_project/meshes/lds_base.dae" scale="0.001 0.001 0.001"/> -->
        <box size="0.0947 0.0727 0.0257"/>
      </geometry>
    </collision>

    <inertial>
      <mass value="0.100"/>
      <inertia ixx="5.0e-05" ixy="0.0e+00" ixz="0.0e+00" iyy="8.0e-05" iyz="0.0e+00" izz="1.2e-04"/>
    </inertial>
  </link>

  <gazebo reference="lidar_support_link">
    <material>Gazebo/DarkGrey</material>
  </gazebo>

  <!-- Lidar spinner link -->
  <link name="lidar_spinner_link">
    <visual>
      <geometry>
        <!-- <mesh filename="package://ros2_urdf_project/meshes/lds_top.dae" scale="0.001 0.001 0.001"/> -->
        <cylinder radius="0.0327" length="0.0188"/>
      </geometry>
      <material name="black"/>
    </visual>

    <collision>
      <geometry>
        <!-- <mesh filename="package://ros2_urdf_project/meshes/lds_top.dae" scale="0.001 0.001 0.001"/> -->
        <cylinder radius="0.0327" length="0.0188"/>
      </geometry>
    </collision>

    <inertial>
      <mass value="0.050"/>
      <inertia ixx="1.5e-05" ixy="0.0e+00" ixz="0.0e+00" iyy="1.5e-05" iyz="0.0e+00" izz="2.7e-05"/>
    </inertial>
  </link>

  <gazebo reference="lidar_spinner_link">
    <material>Gazebo/Black</material>
  </gazebo>

  <!-- Battery link -->
  <link name="battery_link">
    <visual>
      <geometry>
        <box size="0.100 0.035 0.0275"/>
      </geometry>
      <material name="red"/>
    </visual>

    <collision>
      <geometry>
        <box size="0.100 0.035 0.0275"/>
      </geometry>
    </collision>

    <inertial>
      <mass value="0.200"/>
      <inertia ixx="3.3e-05" ixy="0.0e+00" ixz="0.0e+00" iyy="1.8e-04" iyz="0.0e+00" izz="1.9e-04"/>
    </inertial>
  </link>

  <gazebo reference="battery_link">
    <material>Gazebo/Red</material>
  </gazebo>

  <!-- JOINTS -->

    <!-- Chassis plate 1 joint-->
  <joint name="chassis_plate_1_joint" type="fixed">
    <origin rpy="0 0 0" xyz="0 0 0.010"/>
    <parent link="base_link"/>
    <child link="chassis_plate_1_link"/>
  </joint>

  <joint name="spacer45_1_joint" type="fixed">
    <origin rpy="0 0 0" xyz="-0.06375 -0.025 0.018"/>
    <parent link="chassis_plate_1_link"/>
    <child link="spacer45_1_link"/>
  </joint>

  <joint name="spacer45_2_joint" type="fixed">
    <origin rpy="0 0 0" xyz="-0.06375 0.025 0.018"/>
    <parent link="chassis_plate_1_link"/>
    <child link="spacer45_2_link"/>
  </joint>

  <joint name="spacer45_3_joint" type="fixed">
    <origin rpy="0 0 0" xyz="0.06375 -0.025 0.018"/>
    <parent link="chassis_plate_1_link"/>
    <child link="spacer45_3_link"/>
  </joint>

  <joint name="spacer45_4_joint" type="fixed">
    <origin rpy="0 0 0" xyz="0.06375 0.025 0.018"/>
    <parent link="chassis_plate_1_link"/>
    <child link="spacer45_4_link"/>
  </joint>

  <!-- Drive motors joints-->
  <joint name="drive_motor_1_joint" type="fixed">
    <origin rpy="0 0 0" xyz="0.0255 0.05175 0.01875"/>
    <parent link="chassis_plate_1_link"/>
    <child link="drive_motor_1_link"/>
  </joint>

  <joint name="drive_motor_2_joint" type="fixed">
    <origin rpy="0 0 0" xyz="0.0255 -0.05175 0.01875"/>
    <parent link="chassis_plate_1_link"/>
    <child link="drive_motor_2_link"/>
  </joint>

  <!-- Wheel joint -->
  <joint name="left_wheel_joint" type="continuous">
    <origin rpy="0 1.571 1.571" xyz="0.012 0.0259 0"/>
    <parent link="drive_motor_1_link"/>
    <child link="left_wheel_link"/>
    <axis rpy="0 0 0" xyz="0 0 1"/>
    <limit effort="10000" velocity="1000"/>
    <joint_properties damping="1.0" friction="1.0"/>
  </joint>
  
  <joint name="right_wheel_joint" type="continuous">
    <origin rpy="0 1.571 1.571" xyz="0.012 -0.0259 0"/>
    <parent link="drive_motor_2_link"/>
    <child link="right_wheel_link"/>
    <axis rpy="0 0 0" xyz="0 0 1"/>
    <limit effort="10000" velocity="1000"/>
    <joint_properties damping="1.0" friction="1.0"/>
  </joint>

  <!-- Caster wheel joint -->
  <joint name="caster_wheel_support_joint" type="fixed">
    <origin rpy="0 0 0" xyz="-0.04875 0 -0.0085"/>
    <parent link="chassis_plate_1_link"/>
    <child link="caster_wheel_support_link"/>
  </joint>

  <joint name="caster_wheel_yaw_joint" type="continuous">
    <origin rpy="0 0 0" xyz="0 0 -0.004"/>
    <parent link="caster_wheel_support_link"/>
    <child link="caster_wheel_yaw_link"/>
    <axis xyz="0 0 1"/>
    <limit effort="1000.0" velocity="100.0"/>
    <dynamics damping="0.0" friction="0.1"/>
  </joint>

  <joint name="caster_wheel_roll_joint" type="continuous">
    <origin rpy="0 0 0" xyz="0 0 0"/>
    <parent link="caster_wheel_yaw_link"/>
    <child link="caster_wheel_roll_link"/>
    <axis xyz="1 0 0"/>
    <limit effort="1000.0" velocity="100.0"/>
    <dynamics damping="0.0" friction="0.1"/>
  </joint>

  <joint name="caster_wheel_pitch_joint" type="continuous">
    <origin rpy="0 0 0" xyz="0 0 0"/>
    <parent link="caster_wheel_roll_link"/>
    <child link="caster_wheel_pitch_link"/>
    <axis xyz="0 1 0"/>
    <limit effort="1000.0" velocity="100.0"/>
    <dynamics damping="0.0" friction="0.1"/>
  </joint>

  <!-- Battery joint -->
  <joint name="battery_joint" type="fixed">
    <origin rpy="0 0 0" xyz="0.011625 0 0.01825"/>
    <parent link="chassis_plate_1_link"/>
    <child link="battery_link"/>
  </joint>

  <!-- Chassis plate 2 joint-->
  <joint name="chassis_plate_2_joint" type="fixed">
    <origin rpy="0 0 0" xyz="0 0 0.0375"/>
    <parent link="chassis_plate_1_link"/>
    <child link="chassis_plate_2_link"/>
  </joint>

  <joint name="spacer35_1_joint" type="fixed">
    <origin rpy="0 0 0" xyz="-0.024 -0.06375 0.018"/>
    <parent link="chassis_plate_2_link"/>
    <child link="spacer35_1_link"/>
  </joint>

  <joint name="spacer35_2_joint" type="fixed">
    <origin rpy="0 0 0" xyz="-0.024 0.06375 0.018"/>
    <parent link="chassis_plate_2_link"/>
    <child link="spacer35_2_link"/>
  </joint>

  <joint name="spacer35_3_joint" type="fixed">
    <origin rpy="0 0 0" xyz="0.06375 -0.0125 0.018"/>
    <parent link="chassis_plate_2_link"/>
    <child link="spacer35_3_link"/>
  </joint>

  <joint name="spacer35_4_joint" type="fixed">
    <origin rpy="0 0 0" xyz="0.06375 0.0125 0.018"/>
    <parent link="chassis_plate_2_link"/>
    <child link="spacer35_4_link"/>
  </joint>

  <joint name="control_board_joint" type="fixed">
    <origin rpy="0 0 0" xyz="0 0 0.0125"/>
    <parent link="chassis_plate_2_link"/>
    <child link="control_board_link"/>
  </joint>

  <!-- Chassis plate 3 joint-->
  <joint name="chassis_plate_3_joint" type="fixed">
    <origin rpy="0 0 0" xyz="0 0 0.0375"/>
    <parent link="chassis_plate_2_link"/>
    <child link="chassis_plate_3_link"/>
  </joint>

  <joint name="spacer45_5_joint" type="fixed">
    <origin rpy="0 0 0" xyz="0.06375 -0.025 0.018"/>
    <parent link="chassis_plate_3_link"/>
    <child link="spacer45_5_link"/>
  </joint>

  <joint name="spacer45_6_joint" type="fixed">
    <origin rpy="0 0 0" xyz="0.06375 0.025 0.018"/>
    <parent link="chassis_plate_3_link"/>
    <child link="spacer45_6_link"/>
  </joint>

  <joint name="spacer45_7_joint" type="fixed">
    <origin rpy="0 0 0" xyz="0.06375 -0.025 0.018"/>
    <parent link="chassis_plate_3_link"/>
    <child link="spacer45_7_link"/>
  </joint>

  <joint name="spacer45_8_joint" type="fixed">
    <origin rpy="0 0 0" xyz="0.06375 0.025 0.018"/>
    <parent link="chassis_plate_3_link"/>
    <child link="spacer45_8_link"/>
  </joint>

  <joint name="spacer45_9_joint" type="fixed">
    <origin rpy="0 0 0" xyz="0.024 -0.06375 0.018"/>
    <parent link="chassis_plate_3_link"/>
    <child link="spacer45_9_link"/>
  </joint>

  <joint name="spacer45_10_joint" type="fixed">
    <origin rpy="0 0 0" xyz="0.024 0.06375 0.018"/>
    <parent link="chassis_plate_3_link"/>
    <child link="spacer45_10_link"/>
  </joint>

  <!-- Raspberry Pi board joint -->
  <joint name="raspi_board_joint" type="fixed">
    <origin rpy="0 0 0" xyz="-0.030 0 0.01475"/>
    <parent link="chassis_plate_3_link"/>
    <child link="raspi_board_link"/>
  </joint>

  <!-- Lidar USB board joint -->
  <joint name="imu_chip_joint" type="fixed">
    <origin rpy="0 0 0" xyz="0.015 0 0.00675"/>
    <parent link="chassis_plate_3_link"/>
    <child link="imu_chip_link"/>
  </joint>

  <!-- Camera joint -->
  <joint name="camera_support_joint" type="fixed">
    <origin rpy="0 0 0" xyz="0.06625 0 0.01"/>
    <parent link="chassis_plate_3_link"/>
    <child link="camera_support_link"/>
  </joint>

  <joint name="camera_joint" type="fixed">
    <origin rpy="0 0 0" xyz="0.005 0 -0.0075"/>
    <parent link="camera_support_link"/>
    <child link="camera_link"/>
  </joint>

  <!-- Chassis plate 4 joint-->
  <joint name="chassis_plate_4_joint" type="fixed">
    <origin rpy="0 0 0" xyz="0 0 0.0375"/>
    <parent link="chassis_plate_3_link"/>
    <child link="chassis_plate_4_link"/>
  </joint>

  <!-- Lidar -->
  <joint name="lidar_support_joint" type="fixed">
    <origin rpy="0 0 3.142" xyz="0 0 0.01735"/>
    <parent link="chassis_plate_4_link"/>
    <child link="lidar_support_link"/>
  </joint>

  <joint name="lidar_spinner_joint" type="continuous">
    <origin rpy="0 0 0" xyz="0 0 0.02225"/>
    <parent link="lidar_support_link"/>
    <child link="lidar_spinner_link"/>
    <axis xyz="0 0 1"/>
    <limit effort="10.0" velocity="2.0"/>
    <dynamics friction="0.01"/>
  </joint>

  <!-- PLUGINS -->
  <!-- Joint state publisher -->
  <gazebo>
    <plugin name="tb3_burger_joint_state" filename="libgazebo_ros_joint_state_publisher.so">
      <ros>
          <remapping>~/out:=joint_states</remapping>
      </ros>
      <update_rate>30</update_rate>
      <joint_name>left_wheel_joint</joint_name>
      <joint_name>right_wheel_joint</joint_name>
      <joint_name>caster_wheel_yaw_joint</joint_name>
      <joint_name>caster_wheel_roll_joint</joint_name>
      <joint_name>caster_wheel_pitch_joint</joint_name>
      <joint_name>lidar_spinner_joint</joint_name>
    </plugin>
  </gazebo>

  <!-- Differential drive -->
  <gazebo>
    <plugin filename="libgazebo_ros_diff_drive.so" name="differential_drive_controller">

      <!-- wheels -->
      <left_joint>left_wheel_joint</left_joint>
      <right_joint>right_wheel_joint</right_joint>

      <!-- kinematics -->
      <wheel_separation>0.1375</wheel_separation>
      <wheel_diameter>0.066</wheel_diameter>

      <!-- limits -->
      <max_wheel_torque>1.0</max_wheel_torque>
      <max_wheel_acceleration>2.0</max_wheel_acceleration>

      <!-- output -->
      <publish_odom>true</publish_odom>
      <publish_odom_tf>true</publish_odom_tf>

      <odometry_frame>odom</odometry_frame>
      <robot_base_frame>base_link</robot_base_frame>

    </plugin>
  </gazebo>

  <!-- SENSORS -->
  <gazebo reference="lidar_spinner_link">
    <sensor name="sensor_ray" type="ray">
        <pose>0 0 0 0 0 0</pose>
        <ray>
          <scan>
            <horizontal>
              <samples>200</samples>
              <resolution>1.0</resolution>
              <min_angle>-3.14</min_angle>
              <max_angle>3.14</max_angle>
            </horizontal>
          </scan>
          <range>
            <min>0.1</min>
            <max>5.0</max>
          </range>
        </ray>
        <always_on>true</always_on>
        <visualize>true</visualize>
        <update_rate>100.0</update_rate>
        <plugin name="laser" filename="libgazebo_ros_ray_sensor.so">
          <ros>
            <namespace>/tb3_burger</namespace>
            <remapping>~/out:=scan</remapping>
          </ros>
          <output_type>sensor_msgs/LaserScan</output_type>
        </plugin>
      </sensor>
	</gazebo>

    <gazebo reference="camera_link">
      <sensor name="camera" type="camera">
        <update_rate>30.0</update_rate>
        <always_on>1</always_on>
        <camera name="camera">
          <horizontal_fov>1.3962634</horizontal_fov>
          <image>
            <width>480</width>
            <height>360</height>
            <format>R8G8B8</format>
          </image>
          <clip>
          <!-- distance described in meters -->
            <near>0.01</near>
            <far>20</far>
          </clip>
          <distortion>
            <k1>0.0</k1>
            <k2>0.0</k2>
            <k3>0.0</k3>
            <p1>0.0</p1>
            <p2>0.0</p2>
            <center>0.5 0.5</center>
          </distortion>
        </camera>
        <plugin filename="libgazebo_ros_camera.so" name="camera_controller">
        <ros>
          <namespace>/tb3_burger</namespace>
          <remapping>~/image_raw:=camera1/image</remapping>
          <remapping>~/camera_info:=camera1/camera_info</remapping>
        </ros>
          <camera_name>camera_low</camera_name>
          <frame_name>camera_link</frame_name>
        </plugin>
      </sensor>
    </gazebo>

    <gazebo reference="imu_chip_link">
      <sensor name="br_imu" type="imu">
        <always_on>true</always_on>
        <update_rate>100</update_rate>
        <imu>
          <angular_velocity>
            <x>
              <noise type="gaussian">
                <mean>0.0</mean>
                <stddev>2e-4</stddev>
              </noise>
            </x>
            <y>
              <noise type="gaussian">
                <mean>0.0</mean>
                <stddev>2e-4</stddev>
              </noise>
            </y>
            <z>
              <noise type="gaussian">
                <mean>0.0</mean>
                <stddev>2e-4</stddev>
              </noise>
            </z>
          </angular_velocity>
          <linear_acceleration>
            <x>
              <noise type="gaussian">
                <mean>0.0</mean>
                <stddev>1.7e-2</stddev>
              </noise>
            </x>
            <y>
              <noise type="gaussian">
                <mean>0.0</mean>
                <stddev>1.7e-2</stddev>
              </noise>
            </y>
            <z>
              <noise type="gaussian">
                <mean>0.0</mean>
                <stddev>1.7e-2</stddev>
              </noise>
            </z>
          </linear_acceleration>
        </imu>
        <plugin name="bytes_imu" filename="libgazebo_ros_imu_sensor.so">
          <ros>
            <namespace>imu</namespace>
            <remapping>~/out:=data</remapping>
          </ros>
          <initial_orientation_as_reference>false</initial_orientation_as_reference>
        </plugin>
      </sensor>
    </gazebo>

    <!-- ROS2 CONTROL -->
  <ros2_control name="GazeboSystem" type="system">
    <hardware>
      <plugin>gazebo_ros2_control/GazeboSystem</plugin>
    </hardware>

    <joint name="lidar_spinner_joint">
      <command_interface name="velocity">
        <param name="min">0.0</param>
        <param name="max">2.0</param>
      </command_interface>
      <state_interface name="position"/>
      <state_interface name="velocity"/>
      <state_interface name="effort"/>
    </joint>
  </ros2_control>

  <gazebo>
    <plugin filename="libgazebo_ros2_control.so" name="gazebo_ros2_control">
      <parameters>$(find ros2_urdf_project)/config/lidar_spin_controller.yaml</parameters>
      <robot_param_node>/robot_state_publisher_node</robot_param_node>
    </plugin>
  </gazebo>

</robot>