<?xml version="1.0"?>
<robot name="tb3_burger">

  <!-- Materials -->
  <material name="white">
      <color rgba="1.0 1.0 1.0 1"/>
  </material>
  
  <material name="black">
    <color rgba="0 0 0 1"/>
  </material>
  
  <material name="dark">
    <color rgba="0.3 0.3 0.3 1"/>
  </material>
  
  <material name="grey">
    <color rgba="0.5 0.5 0.5 1"/>
  </material>
  
  <material name="red">
    <color rgba="0.8 0.0 0.0 1"/>
  </material>
  
  <material name="blue">
    <color rgba="0.0 0.0 0.8 1"/>
  </material>
  
  <material name="green">
    <color rgba="0.0 0.8 0.0 1"/>
  </material>
  
  <material name="yellow">
    <color rgba="0.8 0.8 0.0 1"/>
  </material>

  <material name="magenta">
    <color rgba="0.8 0.0 0.8 1"/>
  </material>
  
  <material name="cyan">
    <color rgba="0.0 0.8 0.8 1"/>
  </material>

  <!-- Base link -->
  <link name="base_link"/>
  
  <!-- Chassis plates link -->
  <link name="chassis_plate_1_link">
    <visual>
      <geometry>
        <box size="0.1375 0.1375 0.009"/>
      </geometry>
      <material name="black"/>
    </visual>

    <collision>
      <geometry>
        <box size="0.1375 0.1375 0.009"/>
      </geometry>
    </collision>

    <inertial>
      <mass value="0.035"/>
      <inertia ixx="5.5e-05" ixy="0.0e+00" ixz="0.0e+00" iyy="5.5e-05" iyz="0.0e+00" izz="1.1e-04"/>
    </inertial>
  </link>

  <link name="chassis_plate_2_link">
    <visual>
      <geometry>
        <box size="0.1375 0.1375 0.009"/>
      </geometry>
      <material name="black"/>
    </visual>

    <collision>
      <geometry>
        <box size="0.1375 0.1375 0.009"/>
      </geometry>
    </collision>

    <inertial>
      <mass value="0.035"/>
      <inertia ixx="5.5e-05" ixy="0.0e+00" ixz="0.0e+00" iyy="5.5e-05" iyz="0.0e+00" izz="1.1e-04"/>
    </inertial>
  </link>

  <link name="chassis_plate_3_link">
    <visual>
      <geometry>
        <box size="0.1375 0.1375 0.009"/>
      </geometry>
      <material name="black"/>
    </visual>

    <collision>
      <geometry>
        <box size="0.1375 0.1375 0.009"/>
      </geometry>
    </collision>

    <inertial>
      <mass value="0.035"/>
      <inertia ixx="5.5e-05" ixy="0.0e+00" ixz="0.0e+00" iyy="5.5e-05" iyz="0.0e+00" izz="1.1e-04"/>
    </inertial>
  </link>

  <link name="chassis_plate_4_link">
    <visual>
      <geometry>
        <box size="0.1375 0.1375 0.009"/>
      </geometry>
      <material name="black"/>
    </visual>

    <collision>
      <geometry>
        <box size="0.1375 0.1375 0.009"/>
      </geometry>
    </collision>

    <inertial>
      <mass value="0.035"/>
      <inertia ixx="5.5e-05" ixy="0.0e+00" ixz="0.0e+00" iyy="5.5e-05" iyz="0.0e+00" izz="1.1e-04"/>
    </inertial>
  </link>

  <!-- PCB mounts links -->
  <!-- <link name="pcb_mount_1_link">
    <visual>
      <geometry>
        <box size="0.03782 0.010 0.010"/>
      </geometry>
      <material name="grey"/>
    </visual>

    <collision>
      <geometry>
        <box size="0.03782 0.010 0.010"/>
      </geometry>
    </collision>

    <inertial>
      <mass value="0.005"/>
      <inertia ixx="8.3e-08" ixy="0.0e+00" ixz="0.0e+00" iyy="6.4e-07" iyz="0.0e+00" izz="6.4e-07"/>
    </inertial>
  </link>

  <link name="pcb_mount_2_link">
    <visual>
      <geometry>
        <box size="0.03782 0.010 0.010"/>
      </geometry>
      <material name="grey"/>
    </visual>

    <collision>
      <geometry>
        <box size="0.03782 0.010 0.010"/>
      </geometry>
    </collision>

    <inertial>
      <mass value="0.005"/>
      <inertia ixx="8.3e-08" ixy="0.0e+00" ixz="0.0e+00" iyy="6.4e-07" iyz="0.0e+00" izz="6.4e-07"/>
    </inertial>
  </link>

  <link name="pcb_mount_3_link">
    <visual>
      <geometry>
        <box size="0.03782 0.010 0.010"/>
      </geometry>
      <material name="grey"/>
    </visual>

    <collision>
      <geometry>
        <box size="0.03782 0.010 0.010"/>
      </geometry>
    </collision>

    <inertial>
      <mass value="0.005"/>
      <inertia ixx="8.3e-08" ixy="0.0e+00" ixz="0.0e+00" iyy="6.4e-07" iyz="0.0e+00" izz="6.4e-07"/>
    </inertial>
  </link>

  <link name="pcb_mount_4_link">
    <visual>
      <geometry>
        <box size="0.03782 0.010 0.010"/>
      </geometry>
      <material name="grey"/>
    </visual>

    <collision>
      <geometry>
        <box size="0.03782 0.010 0.010"/>
      </geometry>
    </collision>

    <inertial>
      <mass value="0.005"/>
      <inertia ixx="8.3e-08" ixy="0.0e+00" ixz="0.0e+00" iyy="6.4e-07" iyz="0.0e+00" izz="6.4e-07"/>
    </inertial>
  </link>

  <link name="pcb_mount_5_link">
    <visual>
      <geometry>
        <box size="0.03782 0.010 0.010"/>
      </geometry>
      <material name="grey"/>
    </visual>

    <collision>
      <geometry>
        <box size="0.03782 0.010 0.010"/>
      </geometry>
    </collision>

    <inertial>
      <mass value="0.005"/>
      <inertia ixx="8.3e-08" ixy="0.0e+00" ixz="0.0e+00" iyy="6.4e-07" iyz="0.0e+00" izz="6.4e-07"/>
    </inertial>
  </link>

  <link name="pcb_mount_6_link">
    <visual>
      <geometry>
        <box size="0.03782 0.010 0.010"/>
      </geometry>
      <material name="grey"/>
    </visual>

    <collision>
      <geometry>
        <box size="0.03782 0.010 0.010"/>
      </geometry>
    </collision>

    <inertial>
      <mass value="0.005"/>
      <inertia ixx="8.3e-08" ixy="0.0e+00" ixz="0.0e+00" iyy="6.4e-07" iyz="0.0e+00" izz="6.4e-07"/>
    </inertial>
  </link>

  <link name="pcb_mount_7_link">
    <visual>
      <geometry>
        <box size="0.03782 0.010 0.010"/>
      </geometry>
      <material name="grey"/>
    </visual>

    <collision>
      <geometry>
        <box size="0.03782 0.010 0.010"/>
      </geometry>
    </collision>

    <inertial>
      <mass value="0.005"/>
      <inertia ixx="8.3e-08" ixy="0.0e+00" ixz="0.0e+00" iyy="6.4e-07" iyz="0.0e+00" izz="6.4e-07"/>
    </inertial>
  </link>

  <link name="pcb_mount_8_link">
    <visual>
      <geometry>
        <box size="0.03782 0.010 0.010"/>
      </geometry>
      <material name="grey"/>
    </visual>

    <collision>
      <geometry>
        <box size="0.03782 0.010 0.010"/>
      </geometry>
    </collision>

    <inertial>
      <mass value="0.005"/>
      <inertia ixx="8.3e-08" ixy="0.0e+00" ixz="0.0e+00" iyy="6.4e-07" iyz="0.0e+00" izz="6.4e-07"/>
    </inertial>
  </link>

  <link name="pcb_mount_9_link">
    <visual>
      <geometry>
        <box size="0.03782 0.010 0.010"/>
      </geometry>
      <material name="grey"/>
    </visual>

    <collision>
      <geometry>
        <box size="0.03782 0.010 0.010"/>
      </geometry>
    </collision>

    <inertial>
      <mass value="0.005"/>
      <inertia ixx="8.3e-08" ixy="0.0e+00" ixz="0.0e+00" iyy="6.4e-07" iyz="0.0e+00" izz="6.4e-07"/>
    </inertial>
  </link>

  <link name="pcb_mount_10_link">
    <visual>
      <geometry>
        <box size="0.03782 0.010 0.010"/>
      </geometry>
      <material name="grey"/>
    </visual>

    <collision>
      <geometry>
        <box size="0.03782 0.010 0.010"/>
      </geometry>
    </collision>

    <inertial>
      <mass value="0.005"/>
      <inertia ixx="8.3e-08" ixy="0.0e+00" ixz="0.0e+00" iyy="6.4e-07" iyz="0.0e+00" izz="6.4e-07"/>
    </inertial>
  </link>

  <link name="pcb_mount_11_link">
    <visual>
      <geometry>
        <box size="0.03782 0.010 0.010"/>
      </geometry>
      <material name="grey"/>
    </visual>

    <collision>
      <geometry>
        <box size="0.03782 0.010 0.010"/>
      </geometry>
    </collision>

    <inertial>
      <mass value="0.005"/>
      <inertia ixx="8.3e-08" ixy="0.0e+00" ixz="0.0e+00" iyy="6.4e-07" iyz="0.0e+00" izz="6.4e-07"/>
    </inertial>
  </link>

  <link name="pcb_mount_12_link">
    <visual>
      <geometry>
        <box size="0.03782 0.010 0.010"/>
      </geometry>
      <material name="grey"/>
    </visual>

    <collision>
      <geometry>
        <box size="0.03782 0.010 0.010"/>
      </geometry>
    </collision>

    <inertial>
      <mass value="0.005"/>
      <inertia ixx="8.3e-08" ixy="0.0e+00" ixz="0.0e+00" iyy="6.4e-07" iyz="0.0e+00" izz="6.4e-07"/>
    </inertial>
  </link> -->
  
  <!-- Spacers (35mm) link -->
  <link name="spacer35_1_link">
    <visual>
      <geometry>
        <cylinder radius="0.0025" length="0.035"/>
      </geometry>
      <material name="grey"/>
    </visual>

    <collision>
      <geometry>
        <cylinder radius="0.0025" length="0.035"/>
      </geometry>
    </collision>

    <inertial>
      <mass value="0.007"/>
      <inertia ixx="7.3e-07" ixy="0.0e+00" ixz="0.0e+00" iyy="7.3e-07" iyz="0.0e+00" izz="2.2e-08"/>
    </inertial>
  </link>
  
  <link name="spacer35_2_link">
    <visual>
      <geometry>
        <cylinder radius="0.0025" length="0.035"/>
      </geometry>
      <material name="grey"/>
    </visual>

    <collision>
      <geometry>
        <cylinder radius="0.0025" length="0.035"/>
      </geometry>
    </collision>

    <inertial>
      <mass value="0.007"/>
      <inertia ixx="7.3e-07" ixy="0.0e+00" ixz="0.0e+00" iyy="7.3e-07" iyz="0.0e+00" izz="2.2e-08"/>
    </inertial>
  </link>
  
  <link name="spacer35_3_link">
    <visual>
      <geometry>
        <cylinder radius="0.0025" length="0.035"/>
      </geometry>
      <material name="grey"/>
    </visual>

    <collision>
      <geometry>
        <cylinder radius="0.0025" length="0.035"/>
      </geometry>
    </collision>

    <inertial>
      <mass value="0.007"/>
      <inertia ixx="7.3e-07" ixy="0.0e+00" ixz="0.0e+00" iyy="7.3e-07" iyz="0.0e+00" izz="2.2e-08"/>
    </inertial>
  </link>
  
  <link name="spacer35_4_link">
    <visual>
      <geometry>
        <cylinder radius="0.0025" length="0.035"/>
      </geometry>
      <material name="grey"/>
    </visual>

    <collision>
      <geometry>
        <cylinder radius="0.0025" length="0.035"/>
      </geometry>
    </collision>

    <inertial>
      <mass value="0.007"/>
      <inertia ixx="7.3e-07" ixy="0.0e+00" ixz="0.0e+00" iyy="7.3e-07" iyz="0.0e+00" izz="2.2e-08"/>
    </inertial>
  </link>
  
  <!-- Spacers (45mm) link -->
  <link name="spacer45_1_link">
    <visual>
      <geometry>
        <cylinder radius="0.0025" length="0.045"/>
      </geometry>
      <material name="grey"/>
    </visual>

    <collision>
      <geometry>
        <cylinder radius="0.0025" length="0.045"/>
      </geometry>
    </collision>

    <inertial>
      <mass value="0.009"/>
      <inertia ixx="1.5e-06" ixy="0.0e+00" ixz="0.0e+00" iyy="1.5e-06" iyz="0.0e+00" izz="2.8e-08"/>
    </inertial>
  </link>
  
  <link name="spacer45_2_link">
    <visual>
      <geometry>
        <cylinder radius="0.0025" length="0.045"/>
      </geometry>
      <material name="grey"/>
    </visual>

    <collision>
      <geometry>
        <cylinder radius="0.0025" length="0.045"/>
      </geometry>
    </collision>

    <inertial>
      <mass value="0.009"/>
      <inertia ixx="1.5e-06" ixy="0.0e+00" ixz="0.0e+00" iyy="1.5e-06" iyz="0.0e+00" izz="2.8e-08"/>
    </inertial>
  </link>
  
  <link name="spacer45_3_link">
    <visual>
      <geometry>
        <cylinder radius="0.0025" length="0.045"/>
      </geometry>
      <material name="grey"/>
    </visual>

    <collision>
      <geometry>
        <cylinder radius="0.0025" length="0.045"/>
      </geometry>
    </collision>

    <inertial>
      <mass value="0.009"/>
      <inertia ixx="1.5e-06" ixy="0.0e+00" ixz="0.0e+00" iyy="1.5e-06" iyz="0.0e+00" izz="2.8e-08"/>
    </inertial>
  </link>
  
  <link name="spacer45_4_link">
    <visual>
      <geometry>
        <cylinder radius="0.0025" length="0.045"/>
      </geometry>
      <material name="grey"/>
    </visual>

    <collision>
      <geometry>
        <cylinder radius="0.0025" length="0.045"/>
      </geometry>
    </collision>

    <inertial>
      <mass value="0.009"/>
      <inertia ixx="1.5e-06" ixy="0.0e+00" ixz="0.0e+00" iyy="1.5e-06" iyz="0.0e+00" izz="2.8e-08"/>
    </inertial>
  </link>
  
  <link name="spacer45_5_link">
    <visual>
      <geometry>
        <cylinder radius="0.0025" length="0.045"/>
      </geometry>
      <material name="grey"/>
    </visual>

    <collision>
      <geometry>
        <cylinder radius="0.0025" length="0.045"/>
      </geometry>
    </collision>

    <inertial>
      <mass value="0.009"/>
      <inertia ixx="1.5e-06" ixy="0.0e+00" ixz="0.0e+00" iyy="1.5e-06" iyz="0.0e+00" izz="2.8e-08"/>
    </inertial>
  </link>
  
  <link name="spacer45_6_link">
    <visual>
      <geometry>
        <cylinder radius="0.0025" length="0.045"/>
      </geometry>
      <material name="grey"/>
    </visual>

    <collision>
      <geometry>
        <cylinder radius="0.0025" length="0.045"/>
      </geometry>
    </collision>

    <inertial>
      <mass value="0.009"/>
      <inertia ixx="1.5e-06" ixy="0.0e+00" ixz="0.0e+00" iyy="1.5e-06" iyz="0.0e+00" izz="2.8e-08"/>
    </inertial>
  </link>
  
  <link name="spacer45_7_link">
    <visual>
      <geometry>
        <cylinder radius="0.0025" length="0.045"/>
      </geometry>
      <material name="grey"/>
    </visual>

    <collision>
      <geometry>
        <cylinder radius="0.0025" length="0.045"/>
      </geometry>
    </collision>

    <inertial>
      <mass value="0.009"/>
      <inertia ixx="1.5e-06" ixy="0.0e+00" ixz="0.0e+00" iyy="1.5e-06" iyz="0.0e+00" izz="2.8e-08"/>
    </inertial>
  </link>
  
  <link name="spacer45_8_link">
    <visual>
      <geometry>
        <cylinder radius="0.0025" length="0.045"/>
      </geometry>
      <material name="grey"/>
    </visual>

    <collision>
      <geometry>
        <cylinder radius="0.0025" length="0.045"/>
      </geometry>
    </collision>

    <inertial>
      <mass value="0.009"/>
      <inertia ixx="1.5e-06" ixy="0.0e+00" ixz="0.0e+00" iyy="1.5e-06" iyz="0.0e+00" izz="2.8e-08"/>
    </inertial>
  </link>
  
  <link name="spacer45_9_link">
    <visual>
      <geometry>
        <cylinder radius="0.0025" length="0.045"/>
      </geometry>
      <material name="grey"/>
    </visual>

    <collision>
      <geometry>
        <cylinder radius="0.0025" length="0.045"/>
      </geometry>
    </collision>

    <inertial>
      <mass value="0.009"/>
      <inertia ixx="1.5e-06" ixy="0.0e+00" ixz="0.0e+00" iyy="1.5e-06" iyz="0.0e+00" izz="2.8e-08"/>
    </inertial>
  </link>
  
  <link name="spacer45_10_link">
    <visual>
      <geometry>
        <cylinder radius="0.0025" length="0.045"/>
      </geometry>
      <material name="grey"/>
    </visual>

    <collision>
      <geometry>
        <cylinder radius="0.0025" length="0.045"/>
      </geometry>
    </collision>

    <inertial>
      <mass value="0.009"/>
      <inertia ixx="1.5e-06" ixy="0.0e+00" ixz="0.0e+00" iyy="1.5e-06" iyz="0.0e+00" izz="2.8e-08"/>
    </inertial>
  </link>

  <!-- Drive motors link -->
  <link name="drive_motor_1_link">
    <visual>
      <geometry>
        <box size="0.0465 0.034 0.0285"/>
      </geometry>
      <material name="grey"/>
    </visual>

    <collision>
      <geometry>
        <box size="0.0465 0.034 0.0285"/>
      </geometry>
    </collision>

    <inertial>
      <mass value="0.050"/>
      <inertia ixx="8.2e-06" ixy="0.0e+00" ixz="0.0e+00" iyy="1.2e-05" iyz="0.0e+00" izz="1.4e-05"/>
    </inertial>
  </link>

  <link name="drive_motor_2_link">
    <visual>
      <geometry>
        <box size="0.0465 0.034 0.0285"/>
      </geometry>
      <material name="grey"/>
    </visual>

    <collision>
      <geometry>
        <box size="0.0465 0.034 0.0285"/>
      </geometry>
    </collision>

    <inertial>
      <mass value="0.050"/>
      <inertia ixx="8.2e-06" ixy="0.0e+00" ixz="0.0e+00" iyy="1.2e-05" iyz="0.0e+00" izz="1.4e-05"/>
    </inertial>
  </link>

  <!-- Drive wheels link -->
  <link name="right_wheel_link">
    <visual>
      <geometry>
        <cylinder radius="0.033" length="0.0178"/>
      </geometry>
      <material name="dark"/>
    </visual>

    <collision>
      <geometry>
        <cylinder radius="0.033" length="0.0178"/>
      </geometry>
    </collision>

    <inertial>
      <mass value="0.025"/>
      <inertia ixx="7.5e-06" ixy="0.0e+00" ixz="0.0e+00" iyy="7.5e-06" iyz="0.0e+00" izz="1.4e-05"/>
    </inertial>
  </link>

  <link name="left_wheel_link">
    <visual>
      <geometry>
        <cylinder radius="0.033" length="0.0178"/>
      </geometry>
      <material name="dark"/>
    </visual>

    <collision>
      <geometry>
        <cylinder radius="0.033" length="0.0178"/>
      </geometry>
    </collision>

    <inertial>
      <mass value="0.025"/>
      <inertia ixx="7.5e-06" ixy="0.0e+00" ixz="0.0e+00" iyy="7.5e-06" iyz="0.0e+00" izz="1.4e-05"/>
    </inertial>
  </link>

  <!-- Caster wheel support link -->
  <link name="caster_wheel_support_link">
    <visual>
      <geometry>
        <box size="0.030 0.018 0.008"/>
      </geometry>
      <material name="dark"/>
    </visual>

    <collision>
      <geometry>
        <box size="0.030 0.018 0.008"/>
      </geometry>
    </collision>

    <inertial>
      <mass value="0.010"/>
      <inertia ixx="3.2e-07" ixy="0.0e+00" ixz="0.0e+00" iyy="8.0e-07" iyz="0.0e+00" izz="1.0e-06"/>
    </inertial>
  </link>

  <!-- Caster wheel link -->
  <link name="caster_wheel_link">
    <visual>
      <geometry>
        <sphere radius="0.005"/>
      </geometry>
      <material name="grey"/>
    </visual>
    
    <collision>
      <geometry>
        <sphere radius="0.005"/>
      </geometry>
    </collision>
    
    <inertial>
      <mass value="0.010"/>
      <inertia ixx="1.0e-07" ixy="0.0e+00" ixz="0.0e+00" iyy="1.0e-07" iyz="0.0e+00" izz="1.0e-07" />
    </inertial>
  </link>

  <link name="caster_yaw_link">
      <visual>
        <geometry>          
          <cylinder length="0.001" radius="0.0025"/>
        </geometry>
        <material name="blue"/>
      </visual>
  </link>

  <link name="caster_roll_link">
      <visual>
        <geometry>
          <cylinder length="0.001" radius="0.0025"/>
        </geometry>
        <material name="red"/>
      </visual>
  </link>

  <link name="caster_pitch_link">
    <visual>
      <geometry>
        <sphere radius="0.005"/>
      </geometry>
      <material name="green"/>
    </visual>
  </link>

  <!-- Control board link -->
  <link name="control_board_link">
    <visual>
      <geometry>
        <box size="0.105 0.075 0.016"/>
      </geometry>
      <material name="blue"/>
    </visual>

    <collision>
      <geometry>
        <box size="0.105 0.075 0.016"/>
      </geometry>
    </collision>

    <inertial>
      <mass value="0.060"/>
      <inertia ixx="2.9e-05" ixy="0.0e+00" ixz="0.0e+00" iyy="5.6e-05" iyz="0.0e+00" izz="8.3e-05"/>
    </inertial>
  </link>

  <!-- IMU chip link -->
  <!-- <link name="imu_chip_link">
    <visual>
      <geometry>
        <box size="0.005 0.005 0.0025"/>
      </geometry>
      <material name="grey"/>
    </visual>

    <collision>
      <geometry>
        <box size="0.005 0.005 0.0025"/>
      </geometry>
    </collision>

    <inertial>
      <mass value="0.002"/>
      <inertia ixx="5.2e-09" ixy="0.0e+00" ixz="0.0e+00" iyy="5.2e-09" iyz="0.0e+00" izz="8.3e-09"/>
    </inertial>
  </link> -->

  <!-- Raspberry Pi board link -->
  <link name="raspi_board_link">
    <visual>
      <geometry>
        <box size="0.058 0.090 0.01935"/>
      </geometry>
      <material name="red"/>
    </visual>

    <collision>
      <geometry>
        <box size="0.058 0.090 0.01935"/>
      </geometry>
    </collision>

    <inertial>
      <mass value="0.050"/>
      <inertia ixx="3.5e-05" ixy="0.0e+00" ixz="0.0e+00" iyy="1.6e-05" iyz="0.0e+00" izz="4.8e-05"/>
    </inertial>
  </link>

  <!-- Lidar USB board link -->
  <link name="lidar_usb_board_link">
    <visual>
      <geometry>
        <box size="0.018 0.030 0.0045"/>
      </geometry>
      <material name="blue"/>
    </visual>

    <collision>
      <geometry>
        <box size="0.018 0.030 0.0045"/>
      </geometry>
    </collision>

    <inertial>
      <mass value="0.010"/>
      <inertia ixx="7.7e-07" ixy="0.0e+00" ixz="0.0e+00" iyy="2.9e-07" iyz="0.0e+00" izz="1.0e-06"/>
    </inertial>
  </link>

  <!-- Camera support link -->
  <!-- <link name="camera_support_link">
    <visual>
      <geometry>
        <box size="0.005 0.030 0.015"/>
      </geometry>
      <material name="white"/>
    </visual>

    <collision>
      <geometry>
        <box size="0.005 0.030 0.015"/>
      </geometry>
    </collision>

    <inertial>
      <mass value="0.010"/>
      <inertia ixx="9.4e-07" ixy="0.0e+00" ixz="0.0e+00" iyy="2.1e-07" iyz="0.0e+00" izz="7.7e-07"/>
    </inertial>
  </link> -->

  <!-- Camera link -->
  <!-- <link name="camera_link">
    <visual>
      <geometry>
        <box size="0.005 0.030 0.030"/>
      </geometry>
      <material name="black"/>
    </visual>

    <collision>
      <geometry>
        <box size="0.005 0.030 0.030"/>
      </geometry>
    </collision>

    <inertial>
      <mass value="0.010"/>
      <inertia ixx="9.4e-07" ixy="0.0e+00" ixz="0.0e+00" iyy="2.1e-07" iyz="0.0e+00" izz="7.7e-07"/>
    </inertial>
  </link> -->

  <!-- Lidar support link -->
  <link name="lidar_support_link">
    <visual>
      <geometry>
        <mesh filename="package://ros2_urdf_project/meshes/lds_base.dae" scale="0.5 0.5 0.5"/>
      </geometry>
      <material name="dark"/>
    </visual>

    <collision>
      <geometry>
        <box size="0.0947 0.0727 0.0257"/>
      </geometry>
    </collision>

    <inertial>
      <mass value="0.100"/>
      <inertia ixx="5.0e-05" ixy="0.0e+00" ixz="0.0e+00" iyy="8.0e-05" iyz="0.0e+00" izz="1.2e-04"/>
    </inertial>
  </link>

  <!-- Lidar spinner link -->
  <link name="lidar_spinner_link">
    <visual>
      <geometry>
        <mesh filename="package://ros2_urdf_project/meshes/lds_top.dae" scale="0.5 0.5 0.5"/>
      </geometry>
      <material name="grey"/>
    </visual>

    <collision>
      <geometry>
        <cylinder radius="0.0327" length="0.0188"/>
      </geometry>
    </collision>

    <inertial>
      <mass value="0.050"/>
      <inertia ixx="1.5e-05" ixy="0.0e+00" ixz="0.0e+00" iyy="1.5e-05" iyz="0.0e+00" izz="2.7e-05"/>
    </inertial>
  </link>

  <!-- Battery link -->
  <link name="battery_link">
    <visual>
      <geometry>
        <box size="0.100 0.035 0.0275"/>
      </geometry>
      <material name="red"/>
    </visual>

    <collision>
      <geometry>
        <box size="0.100 0.035 0.0275"/>
      </geometry>
    </collision>

    <inertial>
      <mass value="0.200"/>
      <inertia ixx="3.3e-05" ixy="0.0e+00" ixz="0.0e+00" iyy="1.8e-04" iyz="0.0e+00" izz="1.9e-04"/>
    </inertial>
  </link>

    <!-- Chassis plate 1 joint-->
  <joint name="chassis_plate_1_joint" type="fixed">
    <origin rpy="0 0 0" xyz="0 0 0.010"/>
    <parent link="base_link"/>
    <child link="chassis_plate_1_link"/>
  </joint>

  <joint name="spacer45_1_joint" type="fixed">
    <origin rpy="0 0 0" xyz="0.06375 -0.025 0.018"/>
    <parent link="chassis_plate_1_link"/>
    <child link="spacer45_1_link"/>
  </joint>

  <joint name="spacer45_2_joint" type="fixed">
    <origin rpy="0 0 0" xyz="0.06375 0.025 0.018"/>
    <parent link="chassis_plate_1_link"/>
    <child link="spacer45_2_link"/>
  </joint>

  <joint name="spacer45_3_joint" type="fixed">
    <origin rpy="0 0 0" xyz="-0.06375 -0.025 0.018"/>
    <parent link="chassis_plate_1_link"/>
    <child link="spacer45_3_link"/>
  </joint>

  <joint name="spacer45_4_joint" type="fixed">
    <origin rpy="0 0 0" xyz="-0.06375 0.025 0.018"/>
    <parent link="chassis_plate_1_link"/>
    <child link="spacer45_4_link"/>
  </joint>

  <!-- Drive motors joints-->
  <joint name="drive_motor_1_joint" type="fixed">
    <origin rpy="0 0 0" xyz="-0.0255 0.05175 0.01875"/>
    <parent link="chassis_plate_1_link"/>
    <child link="drive_motor_1_link"/>
  </joint>

  <joint name="drive_motor_2_joint" type="fixed">
    <origin rpy="0 0 0" xyz="-0.0255 -0.05175 0.01875"/>
    <parent link="chassis_plate_1_link"/>
    <child link="drive_motor_2_link"/>
  </joint>

  <!-- Wheel joint -->
  <joint name="right_wheel_joint" type="continuous">
    <origin rpy="1.571 0 0" xyz="-0.015 0.026 0"/>
    <parent link="drive_motor_1_link"/>
    <child link="right_wheel_link"/>
    <axis rpy="0 0 0" xyz="1 0 0"/>
    <limit effort="10000" velocity="1000"/>
    <dynamics damping="1.0" friction="1.0"/>
  </joint>

  <joint name="left_wheel_joint" type="continuous">
    <origin rpy="1.571 0 0" xyz="-0.015 -0.026 0"/>
    <parent link="drive_motor_2_link"/>
    <child link="left_wheel_link"/>
    <axis rpy="0 0 0" xyz="1 0 0"/>
    <limit effort="10000" velocity="1000"/>
    <dynamics damping="1.0" friction="1.0"/>
  </joint>

  <!-- Caster wheel joint -->
  <joint name="caster_wheel_support_joint" type="fixed">
    <origin rpy="0 0 0" xyz="0.04875 0 -0.0085"/>
    <parent link="chassis_plate_1_link"/>
    <child link="caster_wheel_support_link"/>
  </joint>

  <joint name="caster_wheel_joint" type="fixed">
    <origin rpy="0 0 0" xyz="0 0 -0.004"/>
    <parent link="caster_wheel_support_link"/>
    <child link="caster_wheel_link"/>
  </joint>

  <joint name="caster_yaw_joint" type="continuous">
    <origin rpy="0 0 0" xyz="0 0 -0.004" />
    <parent link="caster_wheel_support_link" />
    <child link="caster_yaw_link" />
    <axis xyz="0 0 1" />
    <limit effort="1000.0" velocity="100.0" />
    <dynamics damping="0.0" friction="0.1"/>
  </joint>

  <joint name="caster_roll_joint" type="continuous">
    <origin rpy="0 0 0" xyz="0 0 0" />
    <parent link="caster_yaw_link" />
    <child link="caster_roll_link" />
    <axis xyz="1 0 0" />
    <limit effort="1000.0" velocity="100.0" />
    <dynamics damping="0.0" friction="0.1"/>
  </joint>

  <joint name="caster_pitch_joint" type="continuous">
    <origin rpy="0 0 0" xyz="0 0 0" />
    <parent link="caster_roll_link" />
    <child link="caster_pitch_link" />
    <axis xyz="0 1 0" />
    <limit effort="1000.0" velocity="100.0" />
    <dynamics damping="0.0" friction="0.1"/>
  </joint>

  <!-- Battery joint -->
  <joint name="battery_joint" type="fixed">
    <origin rpy="0 0 0" xyz="-0.011625 0 0.01825"/>
    <parent link="chassis_plate_1_link"/>
    <child link="battery_link"/>
  </joint>

  <!-- Chassis plate 2 joint-->
  <joint name="chassis_plate_2_joint" type="fixed">
    <origin rpy="0 0 0" xyz="0 0 0.0375"/>
    <parent link="chassis_plate_1_link"/>
    <child link="chassis_plate_2_link"/>
  </joint>

  <joint name="spacer35_1_joint" type="fixed">
    <origin rpy="0 0 0" xyz="0.024 -0.06375 0.018"/>
    <parent link="chassis_plate_2_link"/>
    <child link="spacer35_1_link"/>
  </joint>

  <joint name="spacer35_2_joint" type="fixed">
    <origin rpy="0 0 0" xyz="0.024 0.06375 0.018"/>
    <parent link="chassis_plate_2_link"/>
    <child link="spacer35_2_link"/>
  </joint>

  <joint name="spacer35_3_joint" type="fixed">
    <origin rpy="0 0 0" xyz="-0.06375 -0.015 0.018"/>
    <parent link="chassis_plate_2_link"/>
    <child link="spacer35_3_link"/>
  </joint>

  <joint name="spacer35_4_joint" type="fixed">
    <origin rpy="0 0 0" xyz="-0.06375 0.015 0.018"/>
    <parent link="chassis_plate_2_link"/>
    <child link="spacer35_4_link"/>
  </joint>

  <joint name="control_board_joint" type="fixed">
    <origin rpy="0 0 0" xyz="0 0 0.0125"/>
    <parent link="chassis_plate_2_link"/>
    <child link="control_board_link"/>
  </joint>

  <!-- Chassis plate 3 joint-->
  <joint name="chassis_plate_3_joint" type="fixed">
    <origin rpy="0 0 0" xyz="0 0 0.0375"/>
    <parent link="chassis_plate_2_link"/>
    <child link="chassis_plate_3_link"/>
  </joint>

  <joint name="spacer45_5_joint" type="fixed">
    <origin rpy="0 0 0" xyz="0.06375 -0.025 0.018"/>
    <parent link="chassis_plate_3_link"/>
    <child link="spacer45_5_link"/>
  </joint>

  <joint name="spacer45_6_joint" type="fixed">
    <origin rpy="0 0 0" xyz="0.06375 0.025 0.018"/>
    <parent link="chassis_plate_3_link"/>
    <child link="spacer45_6_link"/>
  </joint>

  <joint name="spacer45_7_joint" type="fixed">
    <origin rpy="0 0 0" xyz="-0.06375 -0.025 0.018"/>
    <parent link="chassis_plate_3_link"/>
    <child link="spacer45_7_link"/>
  </joint>

  <joint name="spacer45_8_joint" type="fixed">
    <origin rpy="0 0 0" xyz="-0.06375 0.025 0.018"/>
    <parent link="chassis_plate_3_link"/>
    <child link="spacer45_8_link"/>
  </joint>

  <joint name="spacer45_9_joint" type="fixed">
    <origin rpy="0 0 0" xyz="-0.024 -0.06375 0.018"/>
    <parent link="chassis_plate_3_link"/>
    <child link="spacer45_9_link"/>
  </joint>

  <joint name="spacer45_10_joint" type="fixed">
    <origin rpy="0 0 0" xyz="-0.024 0.06375 0.018"/>
    <parent link="chassis_plate_3_link"/>
    <child link="spacer45_10_link"/>
  </joint>

  <!-- Raspberry Pi board joint -->
  <joint name="raspi_board_joint" type="fixed">
    <origin rpy="0 0 0" xyz="0.030 0 0.01475"/>
    <parent link="chassis_plate_3_link"/>
    <child link="raspi_board_link"/>
  </joint>

  <!-- Lidar USB board joint -->
  <joint name="lidar_usb_board_joint" type="fixed">
    <origin rpy="0 0 0" xyz="-0.015 0 0.00675"/>
    <parent link="chassis_plate_3_link"/>
    <child link="lidar_usb_board_link"/>
  </joint>

  <!-- Chassis plate 4 joint-->
  <joint name="chassis_plate_4_joint" type="fixed">
    <origin rpy="0 0 0" xyz="0 0 0.0375"/>
    <parent link="chassis_plate_3_link"/>
    <child link="chassis_plate_4_link"/>
  </joint>

  <!-- Lidar -->
  <joint name="lidar_support_joint" type="fixed">
    <origin rpy="0 0 0" xyz="0 0 0.01735"/>
    <parent link="chassis_plate_4_link"/>
    <child link="lidar_support_link"/>
  </joint>

  <joint name="lidar_spinner_joint" type="fixed">
    <origin rpy="0 0 0" xyz="0 0 0.02225"/>
    <parent link="lidar_support_link"/>
    <child link="lidar_spinner_link"/>
  </joint>


</robot>
